<?xml version="1.0"?>
<robot name="Furuta">

  <material name="red">
    <color rgba="0.8 0 0 1"/>
  </material>

  <material name="blue">
    <color rgba="0 0 0.8 1"/>
  </material>
   
  <material name="white">
    <color rgba="1 1 1 1"/>
  </material>

  <link name="world">  </link>

  <link name="pillar">
    <inertial>
      <origin xyz="0 0 0"/>
      <mass value="1"/>
      <inertia ixx="1.0" ixy="0.0" ixz="0.0" iyy="1.0" iyz="0.0" izz="1.0"/>
    </inertial>
    <visual>
      <geometry>
        <cylinder radius="0.006" length="0.2"/>
      </geometry>
      <origin rpy="0 0 0" xyz="0 0 0"/>
      <material name="white"/>
    </visual>
  </link>

  <link name="arm">
    <inertial>
      <origin xyz="0 0 0"/>
      <mass value="0.1192"/>
      <inertia ixx="0.0" ixy="0.0" ixz="0.0" iyy="0.0007399" iyz="0.0" izz="0.0007399"/>
    </inertial>
    <visual>
      <geometry>
        <box size="0.012 0.012 0.2"/>
      </geometry>
      <origin rpy="0 1.57075 0" xyz="0 0 0"/>
      <material name="blue"/>
    </visual>
  </link>

  <link name="axle">
    <inertial>
      <origin xyz="0 0 0"/>
      <mass value=".02099"/>
      <inertia ixx="0.00000006579" ixy="0.0" ixz="0.0" iyy="0.0001099" iyz="0.0" izz="0.0001099"/>
    </inertial>
    <visual>
      <geometry>
        <cylinder radius="0.0019" length="0.2"/>
      </geometry>
      <origin rpy="0 1.57075 0" xyz="0 0 0"/>
      <material name="white"/>
    </visual>
  </link>

  <link name="rod">
    <inertial>
      <origin xyz="0 0 0.1"/>
      <mass value=".02399"/>
      <inertia ixx="0.0006516" ixy="0.0" ixz="0.0" iyy="0.0006516" iyz="0.0" izz="0.000001993"/>
    </inertial>
    <visual>
      <geometry>
        <box size="0.012 0.012 0.2"/>
      </geometry>
      <origin rpy="0 0 0" xyz="0 0 0.1"/>
      <material name="red"/>
    </visual>
  </link>

  <joint name="world_to_pillar" type="fixed">
    <axis xyz="0 0 0"/>
    <origin xyz="0.0 0.0 0.1"/>
    <parent link="world"/>
    <child link="pillar"/>
  </joint>

  <joint name="pillar_to_arm" type="revolute">
    <axis xyz="0 0 1"/>
    <parent link="pillar"/>
    <child link="arm"/>
    <origin xyz="0.0 0.0 0.1"/>
    <dynamics damping="0.0" friction="0.0"/>
  </joint>
  
  <joint name="arm_to_axle" type="revolute">
    <axis xyz="1 0 0"/>
    <parent link="arm"/>
    <child link="axle"/>
    <origin xyz="0 0 0"/>
    <limit effort="80" lower="-6.28" upper="6.28" velocity="15"/>
    <dynamics damping="0.0" friction="0.0"/>
  </joint>
  
  <joint name="axle_to_rod" type="fixed">
    <axis xyz="1 0 0"/>
    <parent link="axle"/>
    <child link="rod"/>
    <origin xyz="0.1 0 0"/>
  </joint>

</robot>