<?xml version="1.0"?>
<robot name="Furuta">

  <material name="red">
    <color rgba="0.8 0 0 1"/>
  </material>

  <material name="blue">
    <color rgba="0 0 0.8 1"/>
  </material>
   
  <material name="white">
    <color rgba="1 1 1 1"/>
  </material>

  <link name="world">  </link>

  <link name="pillar">
    <inertial>
      <origin xyz="0 0 0"/>
      <mass value="1"/>
      <inertia ixx="1.0" ixy="0.0" ixz="0.0" iyy="1.0" iyz="0.0" izz="1.0"/>
    </inertial>
    <visual>
      <geometry>
        <cylinder radius="0.006" length="0.2"/>
      </geometry>
      <origin rpy="0 0 0" xyz="0 0 0"/>
      <material name="white"/>
    </visual>
  </link>

  <link name="arm">
    <inertial>
      <origin xyz="0 0 0"/>
      <mass value="0.106"/>
      <inertia ixx="0.0" ixy="0.0" ixz="0.0" iyy="0.000182" iyz="0.0" izz="0.000182"/>
    </inertial>
    <visual>
      <geometry>
        <box size="0.012 0.012 0.09"/>
      </geometry>
      <origin rpy="0 1.57075 0" xyz="0 0 0"/>
      <material name="blue"/>
    </visual>
  </link>

  <link name="axle">
    <inertial>
      <origin xyz="0 0 0"/>
      <mass value="0.0172"/>
      <inertia ixx="0.00000005894" ixy="0.0" ixz="0.0" iyy="0.00005497" iyz="0.0" izz="0.00005497"/>
    </inertial>
    <visual>
      <geometry>
        <cylinder radius="0.0019" length="0.15"/>
      </geometry>
      <origin rpy="0 1.57075 0" xyz="0 0 0"/>
      <material name="white"/>
    </visual>
  </link>

  <link name="rod">
    <inertial>
      <origin rpy="0 0 0" xyz="0 0 0.1"/>
      <mass value="0.015"/>
      <inertia ixx="0.0001594" ixy="0.0" ixz="0.0" iyy="0.0001594" iyz="0.0" izz="0.000001245"/>
    </inertial>
    <visual>
      <geometry>
        <box size="0.012 0.012 0.125"/>
      </geometry>
      <origin rpy="0 0 0" xyz="0 0 0.0625"/>
      <material name="red"/>
    </visual>
  </link>

  <joint name="world_to_pillar" type="fixed">
    <axis xyz="0 0 0"/>
    <origin xyz="0.0 0.0 0.1"/>
    <parent link="world"/>
    <child link="pillar"/>
  </joint>

  <joint name="pillar_to_arm" type="continuous">
    <axis xyz="0 0 1"/>
    <parent link="pillar"/>
    <child link="arm"/>
    <origin xyz="0.0 0.0 0.1"/>
    <limit effort="1000000000.0" velocity="1000000000"/>
  </joint>
  
  <joint name="arm_to_axle" type="continuous">
    <axis xyz="1 0 0"/>
    <parent link="arm"/>
    <child link="axle"/>
    <origin xyz="0 0 0"/>
  </joint>
  
  <joint name="axle_to_rod" type="continuous">
    <axis xyz="1 0 0"/>
    <parent link="axle"/>
    <child link="rod"/>
    <origin rpy="0 0 0" xyz="0.075 0 0"/>
  </joint>

</robot>
